#VRML_SIM R2023a utf8

EXTERNPROTO "https://raw.githubusercontent.com/cyberbotics/webots/R2023a/projects/objects/backgrounds/protos/TexturedBackground.proto"
EXTERNPROTO "https://raw.githubusercontent.com/cyberbotics/webots/R2023a/projects/objects/backgrounds/protos/TexturedBackgroundLight.proto"
EXTERNPROTO "https://raw.githubusercontent.com/cyberbotics/webots/R2023a/projects/objects/floors/protos/UnevenTerrain.proto"
EXTERNPROTO "https://raw.githubusercontent.com/cyberbotics/webots/R2023a/projects/objects/trees/protos/SimpleTree.proto"

WorldInfo {
  info [
    "Demonstration of the alternate tripod gait using linear and rotational motors."
    "Biologically Inspired Robotics Group (BIRG)"
  ]
  title "Hexapod"
  CFM 0.0001
  ERP 0.6
  basicTimeStep 8
  contactProperties [
    ContactProperties {
      material2 "floor"
      coulombFriction [
        0.5
      ]
    }
  ]
} 
Viewpoint {
  fieldOfView 0.5
  orientation -0.23939131917717818 0.47299357076493415 0.8479203254537822 1.076266920257617
  position -4.599074207333501 -7.795286806383909 6.717151463083364
  follow "hexapod"
  followType "Pan and Tilt Shot"
}
TexturedBackground {
}
UnevenTerrain {
  size 10 10 0.5
  xDimension 21
  yDimension 20
  flatCenter TRUE
}

DEF HEXAPOD Robot {
  translation 0 0 0.56
  children [
    DEF HIP_HINGE_JOINT_L0 HingeJoint {
      jointParameters HingeJointParameters {
        position -0.6997303048790904
        axis 0 0 1
        anchor 0.2 0.05 0
      }
      device [
        RotationalMotor {
          name "hip_motor_l0"
          maxVelocity 5
          minPosition -0.7
          maxPosition 0.7
        }
      ]
      endPoint Solid {
        translation 0.2 0.05 0
        rotation 0 0 -1 0.6997303048790904
        children [
          DEF HIP_SHAPE Shape {
            appearance DEF HIP_APPEARANCE PBRAppearance {
              baseColor 1 0 0
              roughness 1
              metalness 0
            }
            geometry Cylinder {
              height 0.06
              radius 0.02
            }
          }
          DEF FEMUR_TRANS Transform {
            translation 0 0.06 0
            children [
              DEF FEMUR_SHAPE Shape {
                appearance DEF METAL_APPEARANCE PBRAppearance {
                  baseColor 0.5 0.5 0.5
                  roughness 1
                  metalness 0
                }
                geometry Box {
                  size 0.02 0.1 0.02
                }
              }
            ]
          }
          DEF KNEE_TRANS Transform {
            translation 0 0.11 0
            children [
              DEF KNEE_SHAPE Shape {
                appearance DEF KNEE_APPEARANCE PBRAppearance {
                  baseColor 0 0.6 0.2
                  roughness 1
                  metalness 0
                }
                geometry Cylinder {
                  height 0.06
                  radius 0.02
                }
              }
            ]
          }
          DEF KNEE_SLIDER_JOINT_L0 SliderJoint {
            jointParameters JointParameters {
              position -0.00647169282684518
              axis 0 0 -1
              minStop -0.02
              maxStop 0.02
            }
            device [
              LinearMotor {
                name "knee_motor_l0"
                minPosition -0.02
                maxPosition 0.02
                maxForce 25
              }
            ]
            endPoint Solid {
              translation 0 0.11 -0.02352830717315481
              rotation 1 0 0 1.5708
              children [
                DEF TIBIA_TRANS Transform {
                  rotation 1 0 0 1.5708
                  children [
                    DEF TIBIA_SHAPE Shape {
                      appearance USE METAL_APPEARANCE
                      geometry Cylinder {
                        height 0.06
                        radius 0.01
                      }
                    }
                  ]
                }
              ]
              boundingObject USE TIBIA_TRANS
              physics DEF STANDARD_PHYSICS Physics {
              }
            }
          }
        ]
        name "l0"
        boundingObject USE KNEE_TRANS
        physics USE STANDARD_PHYSICS
      }
    }
    DEF HIP_HINGE_JOINT_L1 HingeJoint {
      jointParameters HingeJointParameters {
        position 0.6997278176212344
        axis 0 0 1
        anchor 0 0.05 0
      }
      device [
        RotationalMotor {
          name "hip_motor_l1"
          maxVelocity 5
          minPosition -0.7
          maxPosition 0.7
        }
      ]
      endPoint Solid {
        translation 0 0.05 0
        rotation 0 0 1 0.6997278176212344
        children [
          USE HIP_SHAPE
          USE FEMUR_TRANS
          USE KNEE_TRANS
          DEF KNEE_SLIDER_JOINT_L1 SliderJoint {
            jointParameters JointParameters {
              position 0.01978900035552757
              axis 0 0 -1
              minStop -0.02
              maxStop 0.02
            }
            device [
              LinearMotor {
                name "knee_motor_l1"
                minPosition -0.02
                maxPosition 0.02
                maxForce 25
              }
            ]
            endPoint Solid {
              translation 0 0.11 -0.049789000355527566
              rotation 1 0 0 1.5708
              children [
                USE TIBIA_TRANS
              ]
              boundingObject USE TIBIA_TRANS
              physics USE STANDARD_PHYSICS
            }
          }
        ]
        name "l1"
        boundingObject USE KNEE_TRANS
        physics USE STANDARD_PHYSICS
      }
    }
    DEF HIP_HINGE_JOINT_L2 HingeJoint {
      jointParameters HingeJointParameters {
        position -0.6997357256600651
        axis 0 0 1
        anchor -0.2 0.05 0
      }
      device [
        RotationalMotor {
          name "hip_motor_l2"
          maxVelocity 5
          minPosition -0.7
          maxPosition 0.7
        }
      ]
      endPoint Solid {
        translation -0.2 0.05 0
        rotation 0 0 -1 0.6997357256600653
        children [
          USE HIP_SHAPE
          USE FEMUR_TRANS
          USE KNEE_TRANS
          DEF KNEE_SLIDER_JOINT_L2 SliderJoint {
            jointParameters JointParameters {
              position -0.006471692941027745
              axis 0 0 -1
              minStop -0.02
              maxStop 0.22
            }
            device [
              LinearMotor {
                name "knee_motor_l2"
                minPosition -0.02
                maxPosition 0.02
                maxForce 25
              }
            ]
            endPoint Solid {
              translation 0 0.11 -0.023528307058972256
              rotation 1 0 0 1.5708
              children [
                USE TIBIA_TRANS
              ]
              boundingObject USE TIBIA_TRANS
              physics USE STANDARD_PHYSICS
            }
          }
        ]
        name "l2"
        boundingObject USE KNEE_TRANS
        physics USE STANDARD_PHYSICS
      }
    }
    DEF HIP_HINGE_JOINT_R0 HingeJoint {
      jointParameters HingeJointParameters {
        position 0.6997250598003499
        axis 0 0 1
        anchor 0.2 -0.05 0
      }
      device [
        RotationalMotor {
          name "hip_motor_r0"
          maxVelocity 5
          minPosition -0.7
          maxPosition 0.7
        }
      ]
      endPoint Solid {
        translation 0.2 -0.05 0
        rotation 0 0 1 0.6997250598003497
        children [
          USE HIP_SHAPE
          DEF RIGHT_FEMUR_TRANS Transform {
            translation 0 -0.06 0
            children [
              USE FEMUR_SHAPE
            ]
          }
          DEF RIGHT_KNEE_TRANS Transform {
            translation 0 -0.11 0
            children [
              USE KNEE_SHAPE
            ]
          }
          DEF KNEE_SLIDER_JOINT_R0 SliderJoint {
            jointParameters JointParameters {
              position 0.019789001715592534
              axis 0 0 -1
              minStop -0.02
              maxStop 0.02
            }
            device [
              LinearMotor {
                name "knee_motor_r0"
                minPosition -0.02
                maxPosition 0.02
                maxForce 25
              }
            ]
            endPoint Solid {
              translation 0 -0.11 -0.04978900171559253
              rotation 1 0 0 1.5708
              children [
                USE TIBIA_TRANS
              ]
              boundingObject USE TIBIA_TRANS
              physics USE STANDARD_PHYSICS
            }
          }
        ]
        name "r0"
        boundingObject USE RIGHT_KNEE_TRANS
        physics USE STANDARD_PHYSICS
      }
    }
    DEF HIP_HINGE_JOINT_R1 HingeJoint {
      jointParameters HingeJointParameters {
        position -0.6997354642732927
        axis 0 0 1
        anchor 0 -0.05 0
      }
      device [
        RotationalMotor {
          name "hip_motor_r1"
          maxVelocity 5
          minPosition -0.7
          maxPosition 0.7
        }
      ]
      endPoint Solid {
        translation 0 -0.05 0
        rotation 0 0 -1 0.6997354642732924
        children [
          USE HIP_SHAPE
          USE RIGHT_FEMUR_TRANS
          USE RIGHT_KNEE_TRANS
          DEF KNEE_SLIDER_JOINT_R1 SliderJoint {
            jointParameters JointParameters {
              position -0.006471691622270912
              axis 0 0 -1
              minStop -0.02
              maxStop 0.02
            }
            device [
              LinearMotor {
                name "knee_motor_r1"
                minPosition -0.02
                maxPosition 0.02
                maxForce 25
              }
            ]
            endPoint Solid {
              translation 0 -0.11 -0.02352830837772909
              rotation 1 0 0 1.5708
              children [
                USE TIBIA_TRANS
              ]
              boundingObject USE TIBIA_TRANS
              physics USE STANDARD_PHYSICS
            }
          }
        ]
        name "r1"
        boundingObject USE RIGHT_KNEE_TRANS
        physics USE STANDARD_PHYSICS
      }
    }
    DEF HIP_HINGE_JOINT_R2 HingeJoint {
      jointParameters HingeJointParameters {
        position 0.6997333533081878
        axis 0 0 1
        anchor -0.2 -0.05 0
      }
      device [
        RotationalMotor {
          name "hip_motor_r2"
          maxVelocity 5
          minPosition -0.7
          maxPosition 0.7
        }
      ]
      endPoint Solid {
        translation -0.2 -0.05 0
        rotation 0 0 1 0.699733353308188
        children [
          USE HIP_SHAPE
          USE RIGHT_FEMUR_TRANS
          USE RIGHT_KNEE_TRANS
          DEF KNEE_SLIDER_JOINT_R2 SliderJoint {
            jointParameters JointParameters {
              position 0.01978900160426813
              axis 0 0 -1
              minStop -0.02
              maxStop 0.02
            }
            device [
              LinearMotor {
                name "knee_motor_r2"
                minPosition -0.02
                maxPosition 0.02
                maxForce 25
              }
            ]
            endPoint Solid {
              translation 0 -0.11 -0.04978900160426813
              rotation 1 0 0 1.5708
              children [
                USE TIBIA_TRANS
              ]
              boundingObject USE TIBIA_TRANS
              physics USE STANDARD_PHYSICS
            }
          }
        ]
        name "r2"
        boundingObject USE RIGHT_KNEE_TRANS
        physics USE STANDARD_PHYSICS
      }
    }
    DEF BODY_SHAPE Shape {
      appearance USE METAL_APPEARANCE
      geometry Box {
        size 0.48 0.1 0.05
      }
    }
    PointLight {
      attenuation 0 0 0.1
      location 0 0 3.5
      castShadows TRUE
    }
    PointLight {
      attenuation 0 0 0.1
      location -1 -1 3.5
    }
  ]
  name "hexapod"
  boundingObject USE BODY_SHAPE
  physics USE STANDARD_PHYSICS
  controller "GoToXY"
  supervisor TRUE
}
TexturedBackgroundLight {
}
SimpleTree{
  translation 4 3 0
  height 2
  radius 2
}
SimpleTree{
  translation 3.5 2.5 0
  height 2.5
  radius 1.2
}
SimpleTree{
  translation 4 -4 0
  height 2
  radius 2
}
SimpleTree{
  translation 3.5 -4.5 0
  height 2.5
  radius 1.2
}
SimpleTree{
  translation 4 -1 0
  height 2
  radius 2
}
SimpleTree{
  translation 3.5 0.5 0
  height 2.5
  radius 1.2
}
SimpleTree{
  translation 2.5 4 0
  height 2
  radius 2
}
SimpleTree{
  translation 1 3.5 0
  height 2.5
  radius 1.2
}
