<?xml version="1.0" encoding="utf-8"?>
<!-- This URDF was automatically created by SolidWorks to URDF Exporter! Originally created by Stephen Brawner (brawner@gmail.com) 
     Commit Version: 1.6.0-4-g7f85cfe  Build Version: 1.6.7995.38578
     For more information, please see http://wiki.ros.org/sw_urdf_exporter -->
<robot
  name="legged_robot_UPGRADED_v2">
  <link
    name="base_link">
    <inertial>
      <origin
        xyz="0.016043 -4.2188E-15 0.27"
        rpy="0 0 0" />
      <mass
        value="50" />
      <inertia
        ixx="89.962"
        ixy="-9.0526E-12"
        ixz="-0.00048828"
        iyy="55.655"
        iyz="9.4152E-15"
        izz="126.26" />
    </inertial>
    <visual>
      <origin
        xyz="0 0 0"
        rpy="0 0 0" />
      <geometry>
        <mesh
          filename="$(find agrosim_description)/meshes/legged_robot_upgraded_v1/base_link.STL" />
      </geometry>
      <material
        name="">
        <color
          rgba="0.62745 0.62745 0.62745 1" />
      </material>
    </visual>
    <collision>
      <origin
        xyz="0 0 0"
        rpy="0 0 0" />
      <geometry>
        <mesh
          filename="$(find agrosim_description)/meshes/legged_robot_upgraded_v1/base_link.STL" />
      </geometry>
    </collision>
  </link>
  <link
    name="FR_elbow_link">
    <inertial>
      <origin
        xyz="-1.6054E-13 -0.52008 -0.3608"
        rpy="0 0 0" />
      <mass
        value="8" />
      <inertia
        ixx="5.6431"
        ixy="2.183E-13"
        ixz="3.5798E-14"
        iyy="6.3235"
        iyz="-5.0853E-15"
        izz="1.785" />
    </inertial>
    <visual>
      <origin
        xyz="0 0 0"
        rpy="0 0 0" />
      <geometry>
        <mesh
          filename="$(find agrosim_description)/meshes/legged_robot_upgraded_v1/FR_elbow_link.STL" />
      </geometry>
      <material
        name="">
        <color
          rgba="0.62745 0.62745 0.62745 1" />
      </material>
    </visual>
    <collision>
      <origin
        xyz="0 0 0"
        rpy="0 0 0" />
      <geometry>
        <mesh
          filename="$(find agrosim_description)/meshes/legged_robot_upgraded_v1/FR_elbow_link.STL" />
      </geometry>
    </collision>
  </link>
  <joint
    name="FR_elbow_joint"
    type="revolute">
    <origin
      xyz="0.40434 -0.55 0.55"
      rpy="0 0 0" />
    <parent
      link="base_link" />
    <child
      link="FR_elbow_link" />
    <axis
      xyz="0 0 -1" />
    <limit
      lower="-0.4"
      upper="0.4"
      effort="30000"
      velocity="10" />
    <dynamics
      damping="2.5"
      friction="1" />
  </joint>
  <link
    name="FR_bot_leg_link">
    <inertial>
      <origin
        xyz="4.6629E-15 -1.3878E-16 -0.29013"
        rpy="0 0 0" />
      <mass
        value="5" />
      <inertia
        ixx="3.2389"
        ixy="1.795E-13"
        ixz="-2.0654E-14"
        iyy="3.9791"
        iyz="7.4628E-15"
        izz="1.2131" />
    </inertial>
    <visual>
      <origin
        xyz="0 0 0"
        rpy="0 0 0" />
      <geometry>
        <mesh
          filename="$(find agrosim_description)/meshes/legged_robot_upgraded_v1/FR_bot_leg_link.STL" />
      </geometry>
      <material
        name="">
        <color
          rgba="0.62745 0.62745 0.62745 1" />
      </material>
    </visual>
    <collision>
      <origin
        xyz="0 0 0"
        rpy="0 0 0" />
      <geometry>
        <mesh
          filename="$(find agrosim_description)/meshes/legged_robot_upgraded_v1/FR_bot_leg_link.STL" />
      </geometry>
    </collision>
  </link>
  <joint
    name="FR_bot_leg_joint"
    type="prismatic">
    <origin
      xyz="0 -0.55 -1.105"
      rpy="0 0 0" />
    <parent
      link="FR_elbow_link" />
    <child
      link="FR_bot_leg_link" />
    <axis
      xyz="0 0 1" />
    <limit
      lower="0"
      upper="0.5"
      effort="0.1"
      velocity="10" />
    <dynamics
      damping="1e1"
      friction="1e4" />
  </joint>
  <link
    name="MR_elbow_link">
    <inertial>
      <origin
        xyz="-1.632E-13 -0.52008 -0.3608"
        rpy="0 0 0" />
      <mass
        value="8" />
      <inertia
        ixx="5.6431"
        ixy="2.1824E-13"
        ixz="-3.6437E-14"
        iyy="6.3235"
        iyz="2.6068E-16"
        izz="1.785" />
    </inertial>
    <visual>
      <origin
        xyz="0 0 0"
        rpy="0 0 0" />
      <geometry>
        <mesh
          filename="$(find agrosim_description)/meshes/legged_robot_upgraded_v1/MR_elbow_link.STL" />
      </geometry>
      <material
        name="">
        <color
          rgba="0.62745 0.62745 0.62745 1" />
      </material>
    </visual>
    <collision>
      <origin
        xyz="0 0 0"
        rpy="0 0 0" />
      <geometry>
        <mesh
          filename="$(find agrosim_description)/meshes/legged_robot_upgraded_v1/MR_elbow_link.STL" />
      </geometry>
    </collision>
  </link>
  <joint
    name="MR_elbow_joint"
    type="revolute">
    <origin
      xyz="-0.34566 -0.55 0.55"
      rpy="0 0 0" />
    <parent
      link="base_link" />
    <child
      link="MR_elbow_link" />
    <axis
      xyz="0 0 1" />
    <limit
      lower="-0.4"
      upper="0.4"
      effort="30000"
      velocity="10" />
    <dynamics
      damping="2.5"
      friction="1" />
  </joint>
  <link
    name="MR_bot_leg_link">
    <inertial>
      <origin
        xyz="-3.2196E-15 1.471E-15 -0.29013"
        rpy="0 0 0" />
      <mass
        value="5" />
      <inertia
        ixx="3.2389"
        ixy="3.058E-13"
        ixz="2.111E-14"
        iyy="3.9791"
        iyz="-7.6122E-15"
        izz="1.2131" />
    </inertial>
    <visual>
      <origin
        xyz="0 0 0"
        rpy="0 0 0" />
      <geometry>
        <mesh
          filename="$(find agrosim_description)/meshes/legged_robot_upgraded_v1/MR_bot_leg_link.STL" />
      </geometry>
      <material
        name="">
        <color
          rgba="0.62745 0.62745 0.62745 1" />
      </material>
    </visual>
    <collision>
      <origin
        xyz="0 0 0"
        rpy="0 0 0" />
      <geometry>
        <mesh
          filename="$(find agrosim_description)/meshes/legged_robot_upgraded_v1/MR_bot_leg_link.STL" />
      </geometry>
    </collision>
  </link>
  <joint
    name="MR_bot_leg_joint"
    type="prismatic">
    <origin
      xyz="0 -0.55 -1.105"
      rpy="0 0 0" />
    <parent
      link="MR_elbow_link" />
    <child
      link="MR_bot_leg_link" />
    <axis
      xyz="0 0 1" />
    <limit
      lower="0"
      upper="0.5"
      effort="0.1"
      velocity="10" />
    <dynamics
      damping="1e1"
      friction="1e4" />
  </joint>
  <link
    name="base_back_link">
    <inertial>
      <origin
        xyz="-0.76369 2.0028E-13 -5.0686E-06"
        rpy="0 0 0" />
      <mass
        value="25" />
      <inertia
        ixx="45.819"
        ixy="-9.7887E-12"
        ixz="0.0002031"
        iyy="8.5796"
        iyz="-1.9514E-14"
        izz="44.816" />
    </inertial>
    <visual>
      <origin
        xyz="0 0 0"
        rpy="0 0 0" />
      <geometry>
        <mesh
          filename="$(find agrosim_description)/meshes/legged_robot_upgraded_v1/base_back_link.STL" />
      </geometry>
      <material
        name="">
        <color
          rgba="0.62745 0.62745 0.62745 1" />
      </material>
    </visual>
    <collision>
      <origin
        xyz="0 0 0"
        rpy="0 0 0" />
      <geometry>
        <mesh
          filename="$(find agrosim_description)/meshes/legged_robot_upgraded_v1/base_back_link.STL" />
      </geometry>
    </collision>
  </link>
  <joint
    name="base_back_joint"
    type="fixed">
    <origin
      xyz="-0.69566 0 0.27"
      rpy="0 0 0" />
    <parent
      link="base_link" />
    <child
      link="base_back_link" />
    <axis
      xyz="1 0 0" />
    <limit
      lower="0"
      upper="0.8"
      effort="30000"
      velocity="10" />
    <dynamics
      damping="2.5"
      friction="1" />
  </joint>
  <link
    name="BR_elbow_link">
    <inertial>
      <origin
        xyz="-1.5576E-13 -0.52008 -0.3608"
        rpy="0 0 0" />
      <mass
        value="8" />
      <inertia
        ixx="5.6431"
        ixy="2.1831E-13"
        ixz="-3.6468E-14"
        iyy="6.3235"
        iyz="4.3615E-16"
        izz="1.785" />
    </inertial>
    <visual>
      <origin
        xyz="0 0 0"
        rpy="0 0 0" />
      <geometry>
        <mesh
          filename="$(find agrosim_description)/meshes/legged_robot_upgraded_v1/BR_elbow_link.STL" />
      </geometry>
      <material
        name="">
        <color
          rgba="0.62745 0.62745 0.62745 1" />
      </material>
    </visual>
    <collision>
      <origin
        xyz="0 0 0"
        rpy="0 0 0" />
      <geometry>
        <mesh
          filename="$(find agrosim_description)/meshes/legged_robot_upgraded_v1/BR_elbow_link.STL" />
      </geometry>
    </collision>
  </link>
  <joint
    name="BR_elbow_joint"
    type="revolute">
    <origin
      xyz="-0.79 -0.55 0.28"
      rpy="0 0 0" />
    <parent
      link="base_back_link" />
    <child
      link="BR_elbow_link" />
    <axis
      xyz="0 0 -1" />
    <limit
      lower="-0.4"
      upper="0.4"
      effort="30000"
      velocity="10" />
    <dynamics
      damping="2.5"
      friction="1" />
  </joint>
  <link
    name="BR_bot_leg_link">
    <inertial>
      <origin
        xyz="1.0603E-14 -8.7153E-15 -0.29013"
        rpy="0 0 0" />
      <mass
        value="5" />
      <inertia
        ixx="3.2389"
        ixy="-7.2865E-14"
        ixz="-2.0924E-14"
        iyy="3.9791"
        iyz="5.5216E-15"
        izz="1.2131" />
    </inertial>
    <visual>
      <origin
        xyz="0 0 0"
        rpy="0 0 0" />
      <geometry>
        <mesh
          filename="$(find agrosim_description)/meshes/legged_robot_upgraded_v1/BR_bot_leg_link.STL" />
      </geometry>
      <material
        name="">
        <color
          rgba="0.62745 0.62745 0.62745 1" />
      </material>
    </visual>
    <collision>
      <origin
        xyz="0 0 0"
        rpy="0 0 0" />
      <geometry>
        <mesh
          filename="$(find agrosim_description)/meshes/legged_robot_upgraded_v1/BR_bot_leg_link.STL" />
      </geometry>
    </collision>
  </link>
  <joint
    name="BR_bot_leg_joint"
    type="prismatic">
    <origin
      xyz="0 -0.55 -1.105"
      rpy="0 0 0" />
    <parent
      link="BR_elbow_link" />
    <child
      link="BR_bot_leg_link" />
    <axis
      xyz="0 0 1" />
    <limit
      lower="0"
      upper="0.5"
      effort="0.1"
      velocity="10" />
    <dynamics
      damping="1e1"
      friction="1e4" />
  </joint>
  <link
    name="BL_elbow_link">
    <inertial>
      <origin
        xyz="1.3739E-13 0.52008 -0.3608"
        rpy="0 0 0" />
      <mass
        value="8" />
      <inertia
        ixx="5.6431"
        ixy="1.792E-13"
        ixz="-3.6491E-14"
        iyy="6.3235"
        iyz="8.0624E-16"
        izz="1.785" />
    </inertial>
    <visual>
      <origin
        xyz="0 0 0"
        rpy="0 0 0" />
      <geometry>
        <mesh
          filename="$(find agrosim_description)/meshes/legged_robot_upgraded_v1/BL_elbow_link.STL" />
      </geometry>
      <material
        name="">
        <color
          rgba="0.62745 0.62745 0.62745 1" />
      </material>
    </visual>
    <collision>
      <origin
        xyz="0 0 0"
        rpy="0 0 0" />
      <geometry>
        <mesh
          filename="$(find agrosim_description)/meshes/legged_robot_upgraded_v1/BL_elbow_link.STL" />
      </geometry>
    </collision>
  </link>
  <joint
    name="BL_elbow_joint"
    type="revolute">
    <origin
      xyz="-0.79 0.55 0.28"
      rpy="0 0 0" />
    <parent
      link="base_back_link" />
    <child
      link="BL_elbow_link" />
    <axis
      xyz="0 0 -1" />
    <limit
      lower="-0.4"
      upper="0.4"
      effort="30"
      velocity="10" />
    <dynamics
      damping="2.5"
      friction="1" />
  </joint>
  <link
    name="BL_bot_leg_link">
    <inertial>
      <origin
        xyz="-9.9365E-15 0 -0.29013"
        rpy="0 0 0" />
      <mass
        value="5" />
      <inertia
        ixx="3.2389"
        ixy="1.1467E-13"
        ixz="2.1149E-14"
        iyy="3.9791"
        iyz="-9.9172E-15"
        izz="1.2131" />
    </inertial>
    <visual>
      <origin
        xyz="0 0 0"
        rpy="0 0 0" />
      <geometry>
        <mesh
          filename="$(find agrosim_description)/meshes/legged_robot_upgraded_v1/BL_bot_leg_link.STL" />
      </geometry>
      <material
        name="">
        <color
          rgba="0.62745 0.62745 0.62745 1" />
      </material>
    </visual>
    <collision>
      <origin
        xyz="0 0 0"
        rpy="0 0 0" />
      <geometry>
        <mesh
          filename="$(find agrosim_description)/meshes/legged_robot_upgraded_v1/BL_bot_leg_link.STL" />
      </geometry>
    </collision>
  </link>
  <joint
    name="BL_bot_leg_joint"
    type="prismatic">
    <origin
      xyz="0 0.55 -1.105"
      rpy="0 0 0" />
    <parent
      link="BL_elbow_link" />
    <child
      link="BL_bot_leg_link" />
    <axis
      xyz="0 0 1" />
    <limit
      lower="0"
      upper="0.5"
      effort="0.1"
      velocity="10" />
    <dynamics
      damping="1e1"
      friction="1e4" />
  </joint>
  <link
    name="ML_elbow_link">
    <inertial>
      <origin
        xyz="1.4044E-13 0.52008 -0.3608"
        rpy="0 0 0" />
      <mass
        value="8" />
      <inertia
        ixx="5.6431"
        ixy="1.7845E-13"
        ixz="3.6476E-14"
        iyy="6.3235"
        iyz="-1.1974E-15"
        izz="1.785" />
    </inertial>
    <visual>
      <origin
        xyz="0 0 0"
        rpy="0 0 0" />
      <geometry>
        <mesh
          filename="$(find agrosim_description)/meshes/legged_robot_upgraded_v1/ML_elbow_link.STL" />
      </geometry>
      <material
        name="">
        <color
          rgba="0.62745 0.62745 0.62745 1" />
      </material>
    </visual>
    <collision>
      <origin
        xyz="0 0 0"
        rpy="0 0 0" />
      <geometry>
        <mesh
          filename="$(find agrosim_description)/meshes/legged_robot_upgraded_v1/ML_elbow_link.STL" />
      </geometry>
    </collision>
  </link>
  <joint
    name="ML_elbow_joint"
    type="revolute">
    <origin
      xyz="-0.34566 0.55 0.55"
      rpy="0 0 0" />
    <parent
      link="base_link" />
    <child
      link="ML_elbow_link" />
    <axis
      xyz="0 0 1" />
    <limit
      lower="-0.4"
      upper="0.4"
      effort="30"
      velocity="10" />
    <dynamics
      damping="2.5"
      friction="1" />
  </joint>
  <link
    name="ML_bot_leg_link">
    <inertial>
      <origin
        xyz="1.4888E-13 0.55 -1.3751"
        rpy="0 0 0" />
      <mass
        value="5" />
      <inertia
        ixx="3.2389"
        ixy="1.8619E-13"
        ixz="2.111E-14"
        iyy="3.9791"
        iyz="-8.122E-15"
        izz="1.2131" />
    </inertial>
    <visual>
      <origin
        xyz="0 0 0"
        rpy="0 0 0" />
      <geometry>
        <mesh
          filename="$(find agrosim_description)/meshes/legged_robot_upgraded_v1/ML_bot_leg_link.STL" />
      </geometry>
      <material
        name="">
        <color
          rgba="0.62745 0.62745 0.62745 1" />
      </material>
    </visual>
    <collision>
      <origin
        xyz="0 0 0"
        rpy="0 0 0" />
      <geometry>
        <mesh
          filename="$(find agrosim_description)/meshes/legged_robot_upgraded_v1/ML_bot_leg_link.STL" />
      </geometry>
    </collision>
  </link>
  <joint
    name="ML_bot_leg_joint"
    type="prismatic">
    <origin
      xyz="0 0 0"
      rpy="0 0 0" />
    <parent
      link="ML_elbow_link" />
    <child
      link="ML_bot_leg_link" />
    <axis
      xyz="0 0 1" />
    <limit
      lower="0"
      upper="0.5"
      effort="0.1"
      velocity="10" />
    <dynamics
      damping="1e1"
      friction="1e4" />
  </joint>
  <link
    name="FL_elbow_link">
    <inertial>
      <origin
        xyz="1.4366E-13 0.52008 -0.3608"
        rpy="0 0 0" />
      <mass
        value="8" />
      <inertia
        ixx="5.6431"
        ixy="1.7919E-13"
        ixz="3.5809E-14"
        iyy="6.3235"
        iyz="-5.7261E-16"
        izz="1.785" />
    </inertial>
    <visual>
      <origin
        xyz="0 0 0"
        rpy="0 0 0" />
      <geometry>
        <mesh
          filename="$(find agrosim_description)/meshes/legged_robot_upgraded_v1/FL_elbow_link.STL" />
      </geometry>
      <material
        name="">
        <color
          rgba="0.62745 0.62745 0.62745 1" />
      </material>
    </visual>
    <collision>
      <origin
        xyz="0 0 0"
        rpy="0 0 0" />
      <geometry>
        <mesh
          filename="$(find agrosim_description)/meshes/legged_robot_upgraded_v1/FL_elbow_link.STL" />
      </geometry>
    </collision>
  </link>
  <joint
    name="FL_elbow_joint"
    type="revolute">
    <origin
      xyz="0.40434 0.55 0.55"
      rpy="0 0 0" />
    <parent
      link="base_link" />
    <child
      link="FL_elbow_link" />
    <axis
      xyz="0 0 -1" />
    <limit
      lower="-0.4"
      upper="0.4"
      effort="30"
      velocity="10" />
    <dynamics
      damping="2.5"
      friction="1" />
  </joint>
  <link
    name="FL_bot_leg_link">
    <inertial>
      <origin
        xyz="-9.3259E-15 2.2204E-15 -0.30013"
        rpy="0 0 0" />
      <mass
        value="5" />
      <inertia
        ixx="3.2389"
        ixy="-8.7696E-14"
        ixz="-2.0931E-14"
        iyy="3.9791"
        iyz="5.9439E-15"
        izz="1.2131" />
    </inertial>
    <visual>
      <origin
        xyz="0 0 0"
        rpy="0 0 0" />
      <geometry>
        <mesh
          filename="$(find agrosim_description)/meshes/legged_robot_upgraded_v1/FL_bot_leg_link.STL" />
      </geometry>
      <material
        name="">
        <color
          rgba="0.62745 0.62745 0.62745 1" />
      </material>
    </visual>
    <collision>
      <origin
        xyz="0 0 0"
        rpy="0 0 0" />
      <geometry>
        <mesh
          filename="$(find agrosim_description)/meshes/legged_robot_upgraded_v1/FL_bot_leg_link.STL" />
      </geometry>
    </collision>
  </link>
  <joint
    name="FL_bot_leg_joint"
    type="prismatic">
    <origin
      xyz="0 0.55 -1.105"
      rpy="0 0 0" />
    <parent
      link="FL_elbow_link" />
    <child
      link="FL_bot_leg_link" />
    <axis
      xyz="0 0 1" />
    <limit
      lower="0"
      upper="0.5"
      effort="0.1"
      velocity="10" />
    <dynamics
      damping="1e1"
      friction="1e4" />
  </joint>
  
  <gazebo reference="FL_bot_leg_link">

    <mu1>1.0e0</mu1>
    <mu2>1.0e0</mu2>
    <kp>1.0e6</kp>
    <kd>1.0e3</kd>
    <fdir1>0 1 0</fdir1>
  </gazebo>
  
  <gazebo reference="FR_bot_leg_link">

    <mu1>1.0e0</mu1>
    <mu2>1.0e0</mu2>
    <kp>1.0e6</kp>
    <kd>1.0e3</kd>
    <fdir1>0 1 0</fdir1>
  </gazebo>
  <gazebo reference="ML_bot_leg_link">

    <mu1>1.0e0</mu1>
    <mu2>1.0e0</mu2>
    <kp>1.0e6</kp>
    <kd>1.0e3</kd>
    <fdir1>0 1 0</fdir1>
  </gazebo>
  <gazebo reference="MR_bot_leg_link">

    <mu1>1.0e0</mu1>
    <mu2>1.0e0</mu2>
    <kp>1.0e6</kp>
    <kd>1.0e3</kd>
    <fdir1>0 1 0</fdir1>
  </gazebo>
  <gazebo reference="BL_bot_leg_link">

    <mu1>1.0e0</mu1>
    <mu2>1.0e0</mu2>
    <kp>1.0e6</kp>
    <kd>1.0e3</kd>
    <fdir1>0 1 0</fdir1>
  </gazebo>
  <gazebo reference="BR_bot_leg_link">

    <mu1>1.0e0</mu1>
    <mu2>1.0e0</mu2>
    <kp>1.0e6</kp>
    <kd>1.0e3</kd>
    <fdir1>0 1 0</fdir1>
  </gazebo>

  <!-- ros_control plugin
  <gazebo>
    <plugin name="gazebo_ros_control"
            filename="libgazebo_ros_control.so">
      <robotNamespace>/box_bot</robotNamespace>
      <robotParam>/robot_description</robotParam>
      <robotSimType>gazebo_ros_control/DefaultRobotHWSim</robotSimType>
    </plugin>
  </gazebo> -->

    <ros2_control name="GazeboSystem" type="system">
    <hardware>
      <plugin>gazebo_ros2_control/GazeboSystem</plugin>
    </hardware>
        
    <joint name="base_back_joint">
      <command_interface name="position">
        <param name="min">-0.6</param>
        <param name="max">0.6</param>
      </command_interface>
      <state_interface name="position">
        <param name="initial_value">0.3</param>
      </state_interface>
      <state_interface name="velocity"/>
      <state_interface name="effort"/>
    </joint>
    <joint name="FL_elbow_joint">
      <command_interface name="position">
        <param name="min">-0.6</param>
        <param name="max">0.6</param>
      </command_interface>
      <state_interface name="position"/>
      <state_interface name="velocity"/>
      <state_interface name="effort"/>
    </joint>
    <joint name="FL_bot_leg_joint">
      <command_interface name="position">
        <param name="min">0.0</param>
        <param name="max">0.5</param>
      </command_interface>
      <state_interface name="position">
        <param name="initial_value">0.3</param>
      </state_interface>
      <state_interface name="velocity"/>
      <state_interface name="effort"/>
    </joint>
    <joint name="FR_elbow_joint">
      <command_interface name="position">
        <param name="min">-0.6</param>
        <param name="max">0.6</param>
      </command_interface>
      <state_interface name="position"/>
      <state_interface name="velocity"/>
      <state_interface name="effort"/>
    </joint>
    <joint name="FR_bot_leg_joint">
      <command_interface name="position">
        <param name="min">0.0</param>
        <param name="max">0.5</param>
      </command_interface>
      <state_interface name="position">
        <param name="initial_value">0.3</param>
      </state_interface>
      <state_interface name="velocity"/>
      <state_interface name="effort"/>
    </joint>
    <joint name="ML_elbow_joint">
      <command_interface name="position">
        <param name="min">-0.6</param>
        <param name="max">0.6</param>
      </command_interface>
      <state_interface name="position"/>
      <state_interface name="velocity"/>
      <state_interface name="effort"/>
    </joint>
    <joint name="ML_bot_leg_joint">
      <command_interface name="position">
        <param name="min">0.0</param>
        <param name="max">0.5</param>
      </command_interface>
      <state_interface name="position">
        <param name="initial_value">0.3</param>
      </state_interface>
      <state_interface name="velocity"/>
      <state_interface name="effort"/>
    </joint>
    <joint name="MR_elbow_joint">
      <command_interface name="position">
        <param name="min">-0.6</param>
        <param name="max">0.6</param>
      </command_interface>
      <state_interface name="position"/>
      <state_interface name="velocity"/>
      <state_interface name="effort"/>
    </joint>
    <joint name="MR_bot_leg_joint">
      <command_interface name="position">
        <param name="min">0.0</param>
        <param name="max">0.5</param>
      </command_interface>
      <state_interface name="position">
        <param name="initial_value">0.3</param>
      </state_interface>
      <state_interface name="velocity"/>
      <state_interface name="effort"/>
    </joint>
    <joint name="BL_elbow_joint">
      <command_interface name="position">
        <param name="min">-0.6</param>
        <param name="max">0.6</param>
      </command_interface>
      <state_interface name="position"/>
      <state_interface name="velocity"/>
      <state_interface name="effort"/>
    </joint>
    <joint name="BL_bot_leg_joint">
      <command_interface name="position">
        <param name="min">0.0</param>
        <param name="max">0.5</param>
      </command_interface>
      <state_interface name="position">
        <param name="initial_value">0.3</param>
      </state_interface>
      <state_interface name="velocity"/>
      <state_interface name="effort"/>
    </joint>
    <joint name="BR_elbow_joint">
      <command_interface name="position">
        <param name="min">-0.6</param>
        <param name="max">0.6</param>
      </command_interface>
      <state_interface name="position"/>
      <state_interface name="velocity"/>
      <state_interface name="effort"/>
    </joint>
    <joint name="BR_bot_leg_joint">
      <command_interface name="position">
        <param name="min">0.0</param>
        <param name="max">0.5</param>
      </command_interface>
      <state_interface name="position">
        <param name="initial_value">0.3</param>
      </state_interface>
      <state_interface name="velocity"/>
      <state_interface name="effort"/>
    </joint>

  </ros2_control>


  <gazebo>
  <plugin filename="libgazebo_ros2_control.so" name="gazebo_ros2_control">
    <robot_param>robot_description</robot_param>
    <robot_param_node>robot_state_publisher</robot_param_node>
    <parameters>$(find agrosim_description)/config/legged_controller_position.yaml</parameters>
  </plugin>
</gazebo>
</robot>